# 异常与处理

1. catch 块
使用 catch 块处理异常，意味着你将会在方法内部的catch块中捕获和处理异常，这样就可以防止异常传播到调用者。

    ```java
    public void readFile(String fileName) {
        try {
            FileReader file = new FileReader(fileName);
            BufferedReader fileInput = new BufferedReader(file);
            // Read file
            fileInput.close();
        } catch (FileNotFoundException e) {
            System.out.println("File not found: " + e.getMessage());
        } catch (IOException e) {
            System.out.println("Error reading file: " + e.getMessage());
        }
    }
    ```

2. throws 声明
使用 throws 声明异常，意味着该方法不处理异常，而是将其抛出给调用者。这种方式允许调用者决定如何处理异常，并且在方法调用链中传播异常。

    ```java
    public void readFile(String fileName) throws FileNotFoundException, IOException {
        FileReader file = new FileReader(fileName);
        BufferedReader fileInput = new BufferedReader(file);
        // Read file
        fileInput.close();
    }
    ```

    然后在调用 readFile 方法的地方，你需要处理异常：

    ```java
    public void someMethod() {
        try {
            readFile("example.txt");
        } catch (FileNotFoundException e) {
            System.out.println("File not found: " + e.getMessage());
        } catch (IOException e) {
            System.out.println("Error reading file: " + e.getMessage());
        }
    }
    ```

    catch：如果你能在方法内部处理异常，并且有适当的恢复或补救措施，可以使用 catch 块。这样可以防止异常传播，避免对调用者造成影响。
    throws：如果方法不能或不应该处理异常，或者希望将异常传播给调用者，让调用者决定如何处理异常，可以使用 throws 声明。这种方式在更高层次上处理异常时尤其有用。

    在实际编程中，有时候可能会结合使用 catch 和 throws。例如，你可以在方法内部捕获并处理部分异常，然后将其他无法处理的异常抛出：

    ```java
    public void readFile(String fileName) throws IOException {
        try {
            FileReader file = new FileReader(fileName);
            BufferedReader fileInput = new BufferedReader(file);
            // Read file
            fileInput.close();
        } catch (FileNotFoundException e) {
            System.out.println("File not found: " + e.getMessage());
            // Re-throw IOException
            throw new IOException("Error occurred while reading the file", e);
        }
    }
    ```

3. throw 关键字
用于显式地抛出异常。可以在方法内部使用，用来生成并抛出一个异常对象。
抛出一个异常后，程序会立即停止执行，并跳转到 catch 块或 finally 块。

    ```java
    public class ExceptionExample {
        public static void main(String[] args) {
            try {
                validateAge(15); // 触发异常
            } catch (Exception e) {
                System.out.println("Exception caught: " + e.getMessage());
            }
        }

        // 使用 throws 声明可能抛出的异常
        public static void validateAge(int age) throws Exception {
            if (age < 18) {
                // 使用 throw 显式抛出异常
                throw new Exception("Age is not valid for voting");
            } else {
                System.out.println("Age is valid for voting");
            }
        }
    }
    ```

    在这个例子中：
    - validateAge 方法使用 throws 声明可能抛出的异常类型Exception。
    - 如果 age 小于 18，validateAge 方法使用 throw 显式抛出一个 Exception 对象。
    - main 方法调用 validateAge 方法，并在 try 块中捕获异常。

    > throw 和 throws 的区别:
    > throw：用于显式地抛出一个异常，可以抛出任何类型的异常（Checked 或 Unchecked）。
    > throws：用于声明一个方法可能抛出的异常类型，主要用于 Checked 异常。调用该方法的代码需要处理或再次声明该异常。

    你还可以定义自己的异常类并使用 throw 关键字来抛出它们。

    ```java{.line-numbers}

    // 自定义异常类
    class InvalidAgeException extends Exception {
        public InvalidAgeException(String message) {
            super(message);
        }
    }

    public class CustomExceptionExample {

        public static void checkAge(int age) throws InvalidAgeException {
            if (age < 18) {
                throw new InvalidAgeException("Age is not valid for voting");
            } else {
                System.out.println("Age is valid for voting");
            }
        }

        public static void main(String[] args) {
            try {
                checkAge(15);
            } catch (InvalidAgeException e) {
                System.out.println("Exception caught: " + e.getMessage());
            }
        }

    }
    ```

4. try-with-resources
   try语句可以使用带资源的语法（try-with-resources），这种语法用于自动管理资源的关闭。try括号中的内容是要声明和自动关闭的资源，通常是实现了AutoCloseable接口的对象。

    ```java
    try (ResourceType resource = new ResourceType()) {
        // 使用资源的代码
    } catch (ExceptionType e) {
        // 异常处理代码
    }
    ```

    这是一个使用try-with-resources创建线程池的例子：

    ```java
    package org.xijuangu;

    import java.util.concurrent.ExecutorService;
    import java.util.concurrent.Executors;

    class MyRunnable2 implements Runnable {     // 实现Runnable接口以创建任务
        public void run() {
            System.out.println(Thread.currentThread().getName());
        }
    }

    public class ThreadPoolDemo{
        public static void main(String[] args) {
            try (ExecutorService pool1 = Executors.newFixedThreadPool(3)) {     // 在try()内创建线程池pool1

                pool1.submit(new MyRunnable2());  // 提交任务给线程池pool1
                pool1.submit(new MyRunnable2());
                pool1.submit(new MyRunnable2());
                pool1.submit(new MyRunnable2());
                pool1.submit(new MyRunnable2());

                //pool1.shutdown();   // 因为自动关闭，不需要再shutdown
            }
        }
    }
    ```
